<?xml version="1.0"?>

<robot xmlns:xacro="http://ros.org/wiki/xacro">
    <xacro:macro name="wheel" params="radius width side parent_link xyz rpy">

        <link name="${side}_wheel_link">
            <visual>
            <geometry>
                <cylinder length="${width}" radius="${radius}"/>
            </geometry>
            <material name="black"/>
            </visual>
            <collision>
            <geometry>
                <cylinder length="${width}" radius="${radius}"/>
            </geometry>
            </collision>
            <inertial>
            <mass value="0.1"/>
            <inertia ixx="5.1458e-5" iyy="5.1458e-5" izz="6.125e-5" ixy="0" ixz="0" iyz="0"/>
            </inertial>
        </link>

        <joint name="${side}_wheel_joint" type="continuous">
            <axis xyz="0 0 1"/>
            <parent link="${parent_link}"/>
            <child link="${side}_wheel_link"/>
            <origin rpy="${rpy}" xyz="${xyz}"/>
        </joint>
    </xacro:macro>
</robot>